ERROR 2019-05-23 15:18:41,245 log Internal Server Error: /cso/webmg/
Traceback (most recent call last):
  File "F:\workspace\xs_venv\lib\site-packages\django\core\handlers\exception.py", line 34, in inner
    response = get_response(request)
  File "F:\workspace\xx-scan\apps\services\middle\MiddleWare.py", line 56, in __call__
    login_superuser(request)
  File "F:\workspace\xx-scan\apps\services\middle\MiddleWare.py", line 34, in login_superuser
    login(request, User.objects.all().filter(is_staff=True)[0])
  File "F:\workspace\xs_venv\lib\site-packages\django\db\models\query.py", line 303, in __getitem__
    return qs._result_cache[0]
IndexError: list index out of range
ERROR 2019-05-23 15:18:41,720 log Internal Server Error: /favicon.ico
Traceback (most recent call last):
  File "F:\workspace\xs_venv\lib\site-packages\django\core\handlers\exception.py", line 34, in inner
    response = get_response(request)
  File "F:\workspace\xx-scan\apps\services\middle\MiddleWare.py", line 56, in __call__
    login_superuser(request)
  File "F:\workspace\xx-scan\apps\services\middle\MiddleWare.py", line 34, in login_superuser
    login(request, User.objects.all().filter(is_staff=True)[0])
  File "F:\workspace\xs_venv\lib\site-packages\django\db\models\query.py", line 303, in __getitem__
    return qs._result_cache[0]
IndexError: list index out of range
WARNING 2019-05-23 15:19:34,483 log Not Found: /favicon.ico
WARNING 2019-05-23 15:19:47,750 log Not Found: /
